[2024-04-09T17:00:41.428+0000] {taskinstance.py:1979} INFO - Dependencies all met for dep_context=non-requeueable deps ti=<TaskInstance: task_states_demo.failed_task scheduled__2023-09-09T00:00:00+00:00 [queued]>
[2024-04-09T17:00:41.622+0000] {taskinstance.py:1979} INFO - Dependencies all met for dep_context=requeueable deps ti=<TaskInstance: task_states_demo.failed_task scheduled__2023-09-09T00:00:00+00:00 [queued]>
[2024-04-09T17:00:41.632+0000] {taskinstance.py:2193} INFO - Starting attempt 1 of 2
[2024-04-09T17:00:41.865+0000] {taskinstance.py:2217} INFO - Executing <Task(BashOperator): failed_task> on 2023-09-09 00:00:00+00:00
[2024-04-09T17:00:41.905+0000] {standard_task_runner.py:60} INFO - Started process 1251 to run task
[2024-04-09T17:00:41.993+0000] {standard_task_runner.py:87} INFO - Running: ['***', 'tasks', 'run', 'task_states_demo', 'failed_task', 'scheduled__2023-09-09T00:00:00+00:00', '--job-id', '198', '--raw', '--subdir', 'DAGS_FOLDER/task_states_demo.py', '--cfg-path', '/tmp/tmp62x2a4qf']
[2024-04-09T17:00:42.056+0000] {standard_task_runner.py:88} INFO - Job 198: Subtask failed_task
[2024-04-09T17:00:42.807+0000] {task_command.py:423} INFO - Running <TaskInstance: task_states_demo.failed_task scheduled__2023-09-09T00:00:00+00:00 [running]> on host fe7355ff6de5
[2024-04-09T17:00:43.920+0000] {taskinstance.py:2513} INFO - Exporting env vars: AIRFLOW_CTX_DAG_EMAIL='your_email@example.com' AIRFLOW_CTX_DAG_OWNER='***' AIRFLOW_CTX_DAG_ID='task_states_demo' AIRFLOW_CTX_TASK_ID='failed_task' AIRFLOW_CTX_EXECUTION_DATE='2023-09-09T00:00:00+00:00' AIRFLOW_CTX_TRY_NUMBER='1' AIRFLOW_CTX_DAG_RUN_ID='scheduled__2023-09-09T00:00:00+00:00'
[2024-04-09T17:00:44.514+0000] {subprocess.py:63} INFO - Tmp dir root location: /tmp
[2024-04-09T17:00:44.804+0000] {subprocess.py:75} INFO - Running command: ['/usr/bin/bash', '-c', 'exit 1']
[2024-04-09T17:00:45.163+0000] {subprocess.py:86} INFO - Output:
[2024-04-09T17:00:45.172+0000] {subprocess.py:97} INFO - Command exited with return code 1
[2024-04-09T17:00:45.297+0000] {taskinstance.py:2731} ERROR - Task failed with exception
Traceback (most recent call last):
  File "/home/airflow/.local/lib/python3.8/site-packages/airflow/models/taskinstance.py", line 444, in _execute_task
    result = _execute_callable(context=context, **execute_callable_kwargs)
  File "/home/airflow/.local/lib/python3.8/site-packages/airflow/models/taskinstance.py", line 414, in _execute_callable
    return execute_callable(context=context, **execute_callable_kwargs)
  File "/home/airflow/.local/lib/python3.8/site-packages/airflow/operators/bash.py", line 212, in execute
    raise AirflowException(
airflow.exceptions.AirflowException: Bash command failed. The command returned a non-zero exit code 1.
[2024-04-09T17:00:45.359+0000] {taskinstance.py:1149} INFO - Marking task as UP_FOR_RETRY. dag_id=task_states_demo, task_id=failed_task, execution_date=20230909T000000, start_date=20240409T170041, end_date=20240409T170045
[2024-04-09T17:00:45.478+0000] {standard_task_runner.py:107} ERROR - Failed to execute job 198 for task failed_task (Bash command failed. The command returned a non-zero exit code 1.; 1251)
[2024-04-09T17:00:45.905+0000] {local_task_job_runner.py:234} INFO - Task exited with return code 1
[2024-04-09T17:00:47.394+0000] {taskinstance.py:3312} INFO - 0 downstream tasks scheduled from follow-on schedule check
