[2024-04-09T17:17:21.862+0000] {taskinstance.py:1979} INFO - Dependencies all met for dep_context=non-requeueable deps ti=<TaskInstance: task_states_demo.failed_task scheduled__2023-10-14T00:00:00+00:00 [queued]>
[2024-04-09T17:17:21.866+0000] {taskinstance.py:1979} INFO - Dependencies all met for dep_context=requeueable deps ti=<TaskInstance: task_states_demo.failed_task scheduled__2023-10-14T00:00:00+00:00 [queued]>
[2024-04-09T17:17:21.866+0000] {taskinstance.py:2193} INFO - Starting attempt 2 of 2
[2024-04-09T17:17:21.873+0000] {taskinstance.py:2217} INFO - Executing <Task(BashOperator): failed_task> on 2023-10-14 00:00:00+00:00
[2024-04-09T17:17:21.878+0000] {standard_task_runner.py:60} INFO - Started process 2358 to run task
[2024-04-09T17:17:21.880+0000] {standard_task_runner.py:87} INFO - Running: ['***', 'tasks', 'run', 'task_states_demo', 'failed_task', 'scheduled__2023-10-14T00:00:00+00:00', '--job-id', '414', '--raw', '--subdir', 'DAGS_FOLDER/task_states_demo.py', '--cfg-path', '/tmp/tmph9wnox6f']
[2024-04-09T17:17:21.883+0000] {standard_task_runner.py:88} INFO - Job 414: Subtask failed_task
[2024-04-09T17:17:21.936+0000] {task_command.py:423} INFO - Running <TaskInstance: task_states_demo.failed_task scheduled__2023-10-14T00:00:00+00:00 [running]> on host fe7355ff6de5
[2024-04-09T17:17:21.970+0000] {taskinstance.py:2513} INFO - Exporting env vars: AIRFLOW_CTX_DAG_EMAIL='your_email@example.com' AIRFLOW_CTX_DAG_OWNER='***' AIRFLOW_CTX_DAG_ID='task_states_demo' AIRFLOW_CTX_TASK_ID='failed_task' AIRFLOW_CTX_EXECUTION_DATE='2023-10-14T00:00:00+00:00' AIRFLOW_CTX_TRY_NUMBER='2' AIRFLOW_CTX_DAG_RUN_ID='scheduled__2023-10-14T00:00:00+00:00'
[2024-04-09T17:17:21.972+0000] {subprocess.py:63} INFO - Tmp dir root location: /tmp
[2024-04-09T17:17:21.972+0000] {subprocess.py:75} INFO - Running command: ['/usr/bin/bash', '-c', 'exit 1']
[2024-04-09T17:17:21.980+0000] {subprocess.py:86} INFO - Output:
[2024-04-09T17:17:21.985+0000] {subprocess.py:97} INFO - Command exited with return code 1
[2024-04-09T17:17:21.994+0000] {taskinstance.py:2731} ERROR - Task failed with exception
Traceback (most recent call last):
  File "/home/airflow/.local/lib/python3.8/site-packages/airflow/models/taskinstance.py", line 444, in _execute_task
    result = _execute_callable(context=context, **execute_callable_kwargs)
  File "/home/airflow/.local/lib/python3.8/site-packages/airflow/models/taskinstance.py", line 414, in _execute_callable
    return execute_callable(context=context, **execute_callable_kwargs)
  File "/home/airflow/.local/lib/python3.8/site-packages/airflow/operators/bash.py", line 212, in execute
    raise AirflowException(
airflow.exceptions.AirflowException: Bash command failed. The command returned a non-zero exit code 1.
[2024-04-09T17:17:21.996+0000] {taskinstance.py:1149} INFO - Marking task as FAILED. dag_id=task_states_demo, task_id=failed_task, execution_date=20231014T000000, start_date=20240409T171721, end_date=20240409T171721
[2024-04-09T17:17:22.004+0000] {standard_task_runner.py:107} ERROR - Failed to execute job 414 for task failed_task (Bash command failed. The command returned a non-zero exit code 1.; 2358)
[2024-04-09T17:17:22.023+0000] {local_task_job_runner.py:234} INFO - Task exited with return code 1
[2024-04-09T17:17:22.036+0000] {taskinstance.py:3312} INFO - 0 downstream tasks scheduled from follow-on schedule check
