[2024-04-09T17:17:37.601+0000] {scheduler_job_runner.py:780} ERROR - Executor reports task instance <TaskInstance: task_states_demo.failed_task scheduled__2023-10-15T00:00:00+00:00 [queued]> finished (failed) although the task says it's queued. (Info: None) Was the task killed externally?
